<?xml version="1.0"?>
<robot xmlns:xacro="http://www.ros.org/wiki/xacro">

    <!--................................ INERTIA MATRICES .............................. -->


    <xacro:macro name="box_inertia" params="mass x y z *origin">
        <inertial>
            <xacro:insert_block name="origin"/>
            <mass value="${mass}" />
            <inertia ixx="${(1/12) * mass * (y*y+z*z)}" ixy="0.0" ixz="0.0"
                    iyy="${(1/12) * mass * (x*x+z*z)}" iyz="0.0"
                    izz="${(1/12) * mass * (x*x+y*y)}" />
        </inertial>
    </xacro:macro>

    <xacro:macro name="inertial_sphere" params="mass radius *origin">
        <inertial>
            <xacro:insert_block name="origin"/>
            <mass value="${mass}" />
            <inertia ixx="${(2/5) * mass * (radius*radius)}" ixy="0.0" ixz="0.0"
                    iyy="${(2/5) * mass * (radius*radius)}" iyz="0.0"
                    izz="${(2/5) * mass * (radius*radius)}" />
        </inertial>
    </xacro:macro>  

    <xacro:macro name="inertial_cylinder" params="mass length radius *origin">
        <inertial>
            <xacro:insert_block name="origin"/>
            <mass value="${mass}" />
            <inertia ixx="${(1/12) * mass * (3*radius*radius + length*length)}" ixy="0.0" ixz="0.0"
                    iyy="${(1/12) * mass * (3*radius*radius + length*length)}" iyz="0.0"
                    izz="${(1/2) * mass * (radius*radius)}" />
        </inertial>
    </xacro:macro>


    <!-- ............................... TROLLEY WHEEL DEFINITION .............................. -->

    <xacro:macro name="trolley_wheel" params="cardinality dexterity origin_x origin_y origin_z">
        <link name="${cardinality}_${dexterity}_wheel">
            <collision>
                <origin xyz="0 0 0" rpy="0 ${pi/2} ${pi/2}" />
                <geometry>
                    <sphere radius="${trolley_wheel_radius}"/>
                </geometry>
            </collision>
            <visual>
                <origin xyz="0 0 0" rpy="0 0 0"/>
                <geometry>
                    <sphere radius="${trolley_wheel_radius}"/>
                </geometry>
                <material name="black">
                    <color rgba="0.0 0.0 0.0 1.0"/>
                </material>
            </visual>

            <inertial>
                <origin xyz="0 0 0" rpy="0 0 0" />
                <mass value="${trolley_wheel_mass}"/>
                <xacro:inertial_sphere mass="${trolley_wheel_mass}" radius="${trolley_wheel_radius}"/>
            </inertial>

            <mu>0.0</mu>
        </link>

        <joint name="${cardinality}_${dexterity}_wheel_joint" type="fixed">
            <parent link="base_link"/>
            <child link="${cardinality}_${dexterity}_wheel"/>
            <origin xyz="${origin_x} ${origin_y} ${origin_z}" rpy="0 0 0" />
            <axis xyz="0 1 0" rpy="0 0 0" />
        </joint>

        <gazebo reference="${cardinality}_${dexterity}_wheel">
            <material>Gazebo/Black</material>
        </gazebo>
    </xacro:macro>

    <xacro:macro name="traction_wheel" params="cardinality dexterity origin_x origin_y origin_z">
        <link name="${cardinality}_${dexterity}_wheel">
            <collision>
                <origin xyz="0 0 0" rpy="0 ${pi/2} ${pi/2}" />
                <geometry>
                    <cylinder length="${traction_wheel_width}" radius="${traction_wheel_radius}"/>
                </geometry>
                <self_collide>false</self_collide>
            </collision>
             <visual>
                <origin xyz="0 0 0" rpy="0 0 0"/>
                
                <geometry>
                    <cylinder radius="${traction_wheel_radius}" length="${traction_wheel_width}"/>
                </geometry>
                <material name="plastic">
                    <color rgba="0.1 0.1 0.1 1"/>
                </material>
            </visual>

            <inertial>
                <origin xyz="0 0 0" rpy="0 ${pi/2} ${pi/2}" />
                <mass value="${traction_wheel_mass}"/>
                <xacro:inertial_cylinder mass="${traction_wheel_mass}" radius="${traction_wheel_radius}" length="${traction_wheel_width}"/>
            </inertial>

            <mu>5.0</mu>
        </link>

        <joint name="${cardinality}_${dexterity}_wheel_joint" type="continuous">
            <parent link="base_link"/>
            <child link="${cardinality}_${dexterity}_wheel"/>
            <origin xyz="${origin_x} ${origin_y} ${origin_z}" rpy="0 0 0" />
            <axis xyz="0 1 0" rpy="0 0 0" />
        </joint>

        <gazebo reference="${cardinality}_${dexterity}_wheel">
            <material>Gazebo/Black</material>
        </gazebo>
    </xacro:macro>

</robot>